Workbook

Sheet MAYO 2024
A1: Consumo Flota Campana MAYO 2024
A5: Unidad | B5: Lts | C5: Kms | D5: Promedio
A6: AA129CZ | B6: 7825 | C6: 19338 | D6: =+B6/C6*100 -> 40.464371
A7: AA850LE | B7: 5055 | C7: 13386 | D7: =+B7/C7*100 -> 37.763335
A8: AB398KI | B8: 4093 | C8: 10335 | D8: =+B8/C8*100 -> 39.60329
A9: AB398KK | B9: 8875 | C9: 23052 | D9: =+B9/C9*100 -> 38.499913
A10: AB398KL | B10: 6353 | C10: 14902 | D10: =+B10/C10*100 -> 42.631861
A11: AB475SV | B11: 2165 | C11: 5393 | D11: =+B11/C11*100 -> 40.144632
A12: AB475SX | B12: 5842 | C12: 16836 | D12: =+B12/C12*100 -> 34.699454
A13: AB475SZ | B13: 6266 | C13: 15086 | D13: =+B13/C13*100 -> 41.535198
A14: AB475TG | B14: 7217 | C14: 16785 | D14: =+B14/C14*100 -> 42.996723
A15: AB475TH | B15: 4525 | C15: 12061 | D15: =+B15/C15*100 -> 37.517619
A16: AB475TI | B16: 5399 | C16: 14223 | D16: =+B16/C16*100 -> 37.959643
A17: AB475TJ | B17: 5777 | C17: 15607 | D17: =+B17/C17*100 -> 37.015442
... A56: AG006FU | B56: 5866 | C56: 13911 | D56: =+B56/C56*100 -> 42.168068
A57: AG006FV | B57: 0 | C57: 0
A58: AG006FY | B58: 6962 | C58: 18886 | D58: =+B58/C58*100 -> 36.863285
A59: AG235ER | B59: 9026 | C59: 23929 | D59: =+B59/C59*100 -> 37.719921
A60: AG326PH | B60: 6008 | C60: 17249 | D60: =+B60/C60*100 -> 34.831005
A61: AG326PT | B61: 6017 | C61: 17165 | D61: =+B61/C61*100 -> 35.053889
A62: AG391AY | B62: 5233 | C62: 14447 | D62: =+B62/C62*100 -> 36.222053
A63: AG391AZ | B63: 6024 | C63: 17265 | D63: =+B63/C63*100 -> 34.891399
A64: AG391BA | B64: 7029 | C64: 20227 | D64: =+B64/C64*100 -> 34.750581
A65: AG391BB | B65: 6889 | C65: 19196 | D65: =+B65/C65*100 -> 35.887685
A66: AG391BC | B66: 6966 | C66: 19296 | D66: =+B66/C66*100 -> 36.100746
A67: AG478GO | B67: 7081 | C67: 20098 | D67: =+B67/C67*100 -> 35.232361
A68: FMO441 | B68: 0 | C68: 0
A69: KHY272 | B69: 5162 | C69: 14728 | D69: =+B69/C69*100 -> 35.048886
A70: LDJ115 | B70: 5448 | C70: 14519 | D70: =+B70/C70*100 -> 37.523245
A71: LIQ701 | B71: 6331 | C71: 16604 | D71: =+B71/C71*100 -> 38.129366
A72: LIQ702 | B72: 4920 | C72: 13753 | D72: =+B72/C72*100 -> 35.774013
A73: LLA868 | B73: 5361 | C73: 13818 | D73: =+B73/C73*100 -> 38.797221
A74: LLA869 | B74: 7131 | C74: 16904 | D74: =+B74/C74*100 -> 42.185282
A75: LLN460 | B75: 4800 | C75: 11883 | D75: =+B75/C75*100 -> 40.39384
A76: LLN461 | B76: 5893 | C76: 14842 | D76: =+B76/C76*100 -> 39.704892
A77: LLN462 | B77: 5489 | C77: 14036 | D77: =+B77/C77*100 -> 39.106583
A78: LLN463 | B78: 5548 | C78: 14080 | D78: =+B78/C78*100 -> 39.403409
A79: LTL641 | B79: 4222 | C79: 11490 | D79: =+B79/C79*100 -> 36.744996
A80: MIA865 | B80: 6349 | C80: 17523 | D80: =+B80/C80*100 -> 36.23238
... A95: OYD518 | B95: 6669 | C95: 16716 | D95: =+B95/C95*100 -> 39.895908
...

Sheet JUNIO 2024
A1: Consumo Flota Campana JUNIO 2024
A5: Unidad | B5: Lts | C5: Kms | D5: Promedio
A6: AF553MI | B6: 6721 | C6: 20359 | D6: =+B6/C6*100 -> 33.012427
A7: AF839EW | B7: 5826 | C7: 17509 | D7: =+B7/C7*100 -> 33.274316
A8: AF086VB | B8: 6505 | C8: 19511 | D8: =+B8/C8*100 -> 33.340167
A9: AF369FA | B9: 6641 | C9: 19876 | D9: =+B9/C9*100 -> 33.412155
A10: AG391BA | B10: 4685 | C10: 13981 | D10: =+B10/C10*100 -> 33.509763
A11: AF140WW | B11: 5995 | C11: 17730 | D11: =+B11/C11*100 -> 33.812747
A12: AF241FJ | B12: 4746 | C12: 14023 | D12: =+B12/C12*100 -> 33.844398
A13: AG006FV | B13: 5164 | C13: 15230 | D13: =+B13/C13*100 -> 33.906763
A14: AF193HQ | B14: 5855 | C14: 17263 | D14: =+B14/C14*100 -> 33.916469
A15: OFU770 | B15: 3705 | C15: 10905 | D15: =+B15/C15*100 -> 33.975241
A16: AF193HH | B16: 8061 | C16: 23635 | D16: =+B16/C16*100 -> 34.106198
A17: AF427QV | B17: 6646 | C17: 19454 | D17: =+B17/C17*100 -> 34.16264
... A29: AE418OT | B29: 6163 | C29: 17553 | D29: =+B29/C29*100 -> 35.110807
A30: AC576YM | B30: =450+5355 -> 5805 | C30: 16498 | D30: =+B30/C30*100 -> 35.186083
A31: AG391AZ | B31: 5873 | C31: 16614 | D31: =+B31/C31*100 -> 35.349705
A32: AG006FY | B32: 7253 | C32: 20428 | D32: =+B32/C32*100 -> 35.505189
A33: AG326PT | B33: 5008 | C33: 14049 | D33: =+B33/C33*100 -> 35.646665
A34: AC576ZN | B34: 5404 | C34: 15155 | D34: =+B34/C34*100 -> 35.658199
A35: KHY272 | B35: 6930 | C35: 19427 | D35: =+B35/C35*100 -> 35.672003
A36: AF304WT | B36: 6217 | C36: 17420 | D36: =+B36/C36*100 -> 35.688863
A37: AF639AI | B37: 6973 | C37: 19522 | D37: =+B37/C37*100 -> 35.718676
A38: AE887HJ | B38: 6737 | C38: 18846 | D38: =+B38/C38*100 -> 35.747639
A39: AF639AJ | B39: 6990 | C39: 19492 | D39: =+B39/C39*100 -> 35.860866
A40: AE418OU | B40: 6342 | C40: 17656 | D40: =+B40/C40*100 -> 35.919801
A41: AF193HG | B41: 7394 | C41: 20567 | D41: =+B41/C41*100 -> 35.950795
A42: AE814AC | B42: 5060 | C42: 14039 | D42: =+B42/C42*100 -> 36.042453
... A83: LLN461 | B83: 4395 | C83: 11276 | D83: =+B83/C83*100 -> 38.976587
A84: AA129CZ | B84: =370+5748 -> 6118 | C84: 15691 | D84: =+B84/C84*100 -> 38.990504
A85: PCK145 | B85: 5506 | C85: 14100 | D85: =+B85/C85*100 -> 39.049645
A86: OWG332 | B86: 5918 | C86: 15063 | D86: =+B86/C86*100 -> 39.288322
A87: NZB192 | B87: 4456 | C87: 11326 | D87: =+B87/C87*100 -> 39.343104
A88: LDJ115 | B88: 5507 | C88: 13905 | D88: =+B88/C88*100 -> 39.604459
A89: AB398KK | B89: 1227 | C89: 3096 | D89: =+B89/C89*100 -> 39.631783
A90: LLN462 | B90: 7096 | C90: 17863 | D90: =+B90/C90*100 -> 39.72457
A91: AC576YL | B91: 7219 | C91: 18100 | D91: =+B91/C91*100 -> 39.883978
A92: NZB193 | B92: 6463 | C92: 16064 | D92: =+B92/C92*100 -> 40.232819
A93: OYE456 | B93: 7957 | C93: 19767 | D93: =+B93/C93*100 -> 40.253959
A94: NZB189 | B94: 4362 | C94: 10826 | D94: =+B94/C94*100 -> 40.29189
...

Sheet JULIO 2024
A1: Consumo Flota Campana JULIO 2024
A5: Unidad | B5: Lts | C5: Kms | D5: Promedio
A6: AF193HH | B6: 7718 | C6: 22790 | D6: =+B6/C6*100 -> 33.865731
A7: AG391AY | B7: 5864 | C7: 17223 | D7: =+B7/C7*100 -> 34.047495
A8: AF369FA | B8: 8577 | C8: 25146 | D8: =+B8/C8*100 -> 34.108805
A9: AG391AZ | B9: 6710 | C9: 19574 | D9: =+B9/C9*100 -> 34.280168
A10: AF140WW | B10: 6953 | C10: 20268 | D10: =+B10/C10*100 -> 34.305309
A11: AF839EW | B11: 5948 | C11: 17292 | D11: =+B11/C11*100 -> 34.397409
A12: AC488KH | B12: 4178 | C12: 12139 | D12: =+B12/C12*100 -> 34.417992
A13: AG006FV | B13: 7957 | C13: 23044 | D13: =+B13/C13*100 -> 34.529596
A14: AF193HQ | B14: 6100 | C14: 17636 | D14: =+B14/C14*100 -> 34.588342
A15: AF241FJ | B15: 5967 | C15: 17211 | D15: =+B15/C15*100 -> 34.669688
A16: AF086VB | B16: 7278 | C16: 20918 | D16: =+B16/C16*100 -> 34.793001
A17: AF553MI | B17: 3753 | C17: 10782 | D17: =+B17/C17*100 -> 34.808013
... A102: LLA869 | B102: 6405 | C102: 15129 | D102: =+B102/C102*100 -> 42.335911
A103: AB475SV
A104: NZB189
A105: Total | B105: =SUM(B6:B104) -> 611270 | C105: =SUM(C6:C104) -> 1633279 | D105: =+B105/C105*100 -> 37.425939

Sheet AGOSTO 2024
A1: Consumo Flota Campana AGOSTO 2024
A5: Unidad | B5: Lts | C5: Kms | D5: Promedio
A6: AA129CZ | B6: 5659.05 | C6: 14296 | D6: =+B6/C6*100 -> 39.584849
A7: AA850LE | B7: 3442 | C7: 8440 | D7: =+B7/C7*100 -> 40.781991
A8: AB398KI | B8: 5907.22 | C8: 14996 | D8: =+B8/C8*100 -> 39.391971
A9: AB398KK | B9: 8499.77 | C9: 22063 | D9: =+B9/C9*100 -> 38.524997
A10: AB398KL | B10: 5929 | C10: 14197 | D10: =+B10/C10*100 -> 41.762344
A11: AB475SV | B11: 2271 | C11: 5894 | D11: =+B11/C11*100 -> 38.530709
A12: AB475SX | B12: 8343.75 | C12: 22461 | D12: =+B12/C12*100 -> 37.147723
A13: AB475SZ | B13: 5785.05 | C13: 14709 | D13: =+B13/C13*100 -> 39.330002
A14: AB475TG | B14: 6284.76 | C14: 16846 | D14: =+B14/C14*100 -> 37.307135
A15: AB475TH | B15: 3407.54 | C15: 8931 | D15: =+B15/C15*100 -> 38.15407
A16: AB475TI | B16: 7142.35 | C16: 18111 | D16: =+B16/C16*100 -> 39.43653
A17: AB475TJ | B17: 7695.19 | C17: 18705 | D17: =+B17/C17*100 -> 41.139749
... A97: OYE456 | B97: 6105.46 | C97: 14332 | D97: =+B97/C97*100 -> 42.600195
A98: OYE471
A99: PCK145 | B99: 6788.83 | C99: 17210 | D99: =+B99/C99*100 -> 39.447008
A100: PCK155 | B100: 5798.35 | C100: 15239 | D100: =+B100/C100*100 -> 38.049413
A101: PCK169 | B101: 6613.55 | C101: 16983 | D101: =+B101/C101*100 -> 38.942177
A102: PNH467 | B102: 3302.01 | C102: 8018 | D102: =+B102/C102*100 -> 41.182464
A103: PNH470 | B103: 6489.9 | C103: 16661 | D103: =+B103/C103*100 -> 38.952644
A104: PNH473 | B104: 7194.99 | C104: 18939 | D104: =+B104/C104*100 -> 37.990337
A105: Total | B105: =SUM(B6:B104) -> 622985.6 | C105: =SUM(C6:C104) -> 1638909 | D105: =+B105/C105*100 -> 38.012214

Sheet SEPTIEMBRE 2024
A1: Consumo Flota Campana SEPTIEMBRE 2024
A5: Unidad | B5: Lts | C5: Kms | D5: Promedio
A6: AA129CZ | B6: 5352 | C6: 13601 | D6: =+B6/C6*100 -> 39.350048
A7: AA850LE | B7: 4604 | C7: 11277 | D7: =+B7/C7*100 -> 40.826461
A8: AB398KI | B8: 3443.11 | C8: 8497 | D8: =+B8/C8*100 -> 40.521478
A9: AB398KK | B9: 5806.99 | C9: 15099 | D9: =+B9/C9*100 -> 38.459434
A10: AB398KL | B10: 5523.87 | C10: 14061 | D10: =+B10/C10*100 -> 39.285044
A11: AB475SV | B11: 6443 | C11: 17112 | D11: =+B11/C11*100 -> 37.65194
A12: AB475SX | B12: 5193.43 | C12: 14106 | D12: =+B12/C12*100 -> 36.81717
A13: AB475SZ | B13: 1090 | C13: 3012 | D13: =+B13/C13*100 -> 36.188579
A14: AB475TG | B14: 4575 | C14: 11889 | D14: =+B14/C14*100 -> 38.480949
A15: AB475TH | B15: 4185.23 | C15: 11460 | D15: =+B15/C15*100 -> 36.520332
A16: AB475TI | B16: 4399 | C16: 11656 | D16: =+B16/C16*100 -> 37.74022
A17: AB475TJ | B17: 2962.87 | C17: 7409 | D17: =+B17/C17*100 -> 39.990147
... A92: OIA800 | B92: 5687.87 | C92: 14223 | D92: =+B92/C92*100 -> 39.990649
A93: OIX583
A94: OUS051 | B94: 6326.04 | C94: 16663 | D94: =+B94/C94*100 -> 37.964592
A95: OWG332 | B95: 5954.92 | C95: 15016 | D95: =+B95/C95*100 -> 39.657166
A96: OYD518 | B96: 6377.25 | C96: 16811 | D96: =+B96/C96*100 -> 37.934983
A97: OYD523 | B97: 8900.58 | C97: 22776 | D97: =+B97/C97*100 -> 39.078767
A98: OYE456 | B98: 5950 | C98: 13867 | D98: =+B98/C98*100 -> 42.907622
A99: PCK145 | B99: 6649.81 | C99: 16504 | D99: =+B99/C99*100 -> 40.292111
A100: PCK155 | B100: 4740 | C100: 12069 | D100: =+B100/C100*100 -> 39.274174
A101: PCK169 | B101: 6148.77 | C101: 16419 | D101: =+B101/C101*100 -> 37.449114
A102: PNH467 | B102: 3284.67 | C102: 8407 | D102: =+B102/C102*100 -> 39.070655
A103: PNH470 | B103: 5462.78 | C103: 14030 | D103: =+B103/C103*100 -> 38.936422
A104: PNH473 | B104: 5929.9 | C104: 16028 | D104: =+B104/C104*100 -> 36.99713
A108: Total | B108: =SUM(B6:B105) -> 562760.77 | C108: =SUM(C6:C105) -> 1504400.3 | D108: =+B108/C108*100 -> 37.407648

Sheet OCTUBRE 2024
A1: Consumo Flota Campana Octubre 2024
A5: Unidad | B5: Lts | C5: Kms | D5: Promedio
A6: AF193HQ | B6: 6095.41 | C6: 19148 | D6: =+B6/C6*100 -> 31.833142
A7: AF140WW | B7: 6180 | C7: 18864 | D7: =+B7/C7*100 -> 32.760814
A8: AG006FV | B8: 7455.94 | C8: 22634 | D8: =+B8/C8*100 -> 32.941327
A9: AF193HH | B9: 7428 | C9: 22225 | D9: =+B9/C9*100 -> 33.421822
A10: AG391AZ | B10: 5951.06 | C10: 17772 | D10: =+B10/C10*100 -> 33.485595
A11: AF639AI | B11: 7248.48 | C11: 21538 | D11: =+B11/C11*100 -> 33.654378
A12: AB475TJ | B12: 6000.28 | C12: 17801 | D12: =+B12/C12*100 -> 33.707545
A13: AG326PH | B13: 8004.81 | C13: 23705 | D13: =+B13/C13*100 -> 33.768445
A14: AF553MI | B14: 4899.93 | C14: 14456 | D14: =+B14/C14*100 -> 33.895476
A15: AF241FJ | B15: 4517.99 | C15: 13283 | D15: =+B15/C15*100 -> 34.013325
A16: AG391BA | B16: 5624 | C16: 16520 | D16: =+B16/C16*100 -> 34.043584
A17: AF369FA | B17: 5761 | C17: 16876 | D17: =+B17/C17*100 -> 34.137236
... A103: LLN460 | B103: 3885 | C103: 8522 | D103: =+B103/C103*100 -> 45.58789
A104: AB398KI
A108: Total | B108: =SUM(B6:B105) -> 557738.37 | C108: =SUM(C6:C107) -> 1511364 | D108: =+B108/C108*100 -> 36.902981

Sheet NOVIEMBRE 2024
A1: Promedio combustible mes Noviembre
A4: Unidad | B4: Litros | C4: Kms | D4: Promedio
A5: AA129CZ | B5: 6545 | C5: 16882 | D5: =B5/C5*100 -> 38.769103
A6: AA850LE | B6: 6623.04 | C6: 16373.06 | D6: =B6/C6*100 -> 40.450838
A7: AB398KK | B7: 3413.97 | C7: 8653.51 | D7: =B7/C7*100 -> 39.451852
A8: AB398KL | B8: 4104.25 | C8: 11046.49 | D8: =B8/C8*100 -> 37.154336
A9: AB475SV | B9: 5204.23 | C9: 14363 | D9: =B9/C9*100 -> 36.233586
A10: AB475SX | B10: 7625.63 | C10: 19637 | D10: =B10/C10*100 -> 38.832968
A11: AB475SZ | B11: 6762 | C11: 16362 | D11: =B11/C11*100 -> 41.327466
A12: AB475TG | B12: 6465 | C12: 17227 | D12: =B12/C12*100 -> 37.528299
A13: AB475TH | B13: 5812 | C13: 14400 | D13: =B13/C13*100 -> 40.361111
A14: AB475TI | B14: 5347 | C14: 13566 | D14: =B14/C14*100 -> 39.414713
A15: AB475TJ | B15: 1098 | C15: 2940 | D15: =B15/C15*100 -> 37.346939
A16: AC488KH | B16: 4118 | C16: 11398 | D16: =B16/C16*100 -> 36.129145
... A28: AE362RY | B28: 6645 | C28: 16883 | D28: =B28/C28*100 -> 39.359119
A29: AE379FQ | B29: 0 | C29: 0
A30: AE418OT | B30: 4054 | C30: 10978 | D30: =B30/C30*100 -> 36.928402
A31: AE418OU | B31: 4944 | C31: 14549 | D31: =B31/C31*100 -> 33.981717
A32: AE450BO | B32: 4559.99 | C32: 12876 | D32: =B32/C32*100 -> 35.414647
A33: AE629VP | B33: 8986.48 | C33: 24158 | D33: =B33/C33*100 -> 37.198775
A34: AE814AC | B34: 5097 | C34: 13807 | D34: =B34/C34*100 -> 36.916057
A35: AE887HJ | B35: 6074 | C35: 16389 | D35: =B35/C35*100 -> 37.061444
A36: AE887HK | B36: 6151 | C36: 16532 | D36: =B36/C36*100 -> 37.20663
A37: AF086VB | B37: 7082 | C37: 20005 | D37: =B37/C37*100 -> 35.40115
A38: AF140WW | B38: 6498 | C38: 18449 | D38: =B38/C38*100 -> 35.221421
A39: AF193HG | B39: 3732.21 | C39: 10427 | D39: =B39/C39*100 -> 35.793709
A40: AF193HH | B40: 4834 | C40: 14529 | D40: =B40/C40*100 -> 33.271388
A41: AF193HQ | B41: 6021 | C41: 18670 | D41: =B41/C41*100 -> 32.249598
... A102: PNH473 | B102: 8390 | C102: 22157 | D102: =B102/C102*100 -> 37.866137
A103: Total general | B103: =SUM(B5:B102) -> 533192.34 | C103: =SUM(C5:C102) -> 1429999.3 | D103: =B103/C103*100 -> 37.286195

Sheet DICIEMBRE 2024
A1: Promedio combustible mes Noviembre
A4: Unidad | B4: Litros | C4: Kms | D4: Promedio
A5: AA129CZ | B5: 4501.14 | C5: 11421 | D5: =B5/C5*100 -> 39.411085
A6: AA850LE | B6: 5961.98 | C6: 13988 | D6: =B6/C6*100 -> 42.622105
A7: AB398KK | B7: 4776.14 | C7: 12384 | D7: =B7/C7*100 -> 38.567022
A8: AB398KL | B8: 5653.48 | C8: 13383 | D8: =B8/C8*100 -> 42.243742
A9: AB475SV | B9: 4040.53 | C9: 11229 | D9: =B9/C9*100 -> 35.98299
A10: AB475SX | B10: 5109.92 | C10: 14028 | D10: =B10/C10*100 -> 36.426575
A11: AB475SZ | B11: 5454.3 | C11: 13673 | D11: =B11/C11*100 -> 39.891026
A12: AB475TG | B12: 3070.12 | C12: 8510 | D12: =B12/C12*100 -> 36.076616
A13: AB475TH | B13: 3943 | C13: 10715 | D13: =B13/C13*100 -> 36.79888
A14: AB475TI | B14: 5761.23 | C14: 15173 | D14: =B14/C14*100 -> 37.970276
A15: AB475TJ | B15: 2800 | C15: 7833 | D15: =B15/C15*100 -> 35.746202
A16: AC488KH | B16: 4034.75 | C16: 11386 | D16: =B16/C16*100 -> 35.436062
... A35: AE887HJ | B35: 5383.54 | C35: 14931 | D35: =B35/C35*100 -> 36.056125
A36: AE887HK | B36: 0 | C36: 0
A37: AF086VB | B37: 5194.3 | C37: 15734 | D37: =B37/C37*100 -> 33.01322
A38: AF140WW | B38: 4971.26 | C38: 15106 | D38: =B38/C38*100 -> 32.909175
A39: AF193HG | B39: 5329.71 | C39: 15121 | D39: =B39/C39*100 -> 35.247074
A40: AF193HH | B40: 6661.64 | C40: 20278 | D40: =B40/C40*100 -> 32.851563
A41: AF193HQ | B41: 4886.36 | C41: 14793 | D41: =B41/C41*100 -> 33.031569
A42: AF241FJ | B42: 5321.09 | C42: 15622 | D42: =B42/C42*100 -> 34.061516
A43: AF304WT | B43: 6873 | C43: 19332 | D43: =B43/C43*100 -> 35.552452
A44: AF369FA | B44: 6038.67 | C44: 17861 | D44: =B44/C44*100 -> 33.809249
A45: AF371QB | B45: 5526.84 | C45: 15572 | D45: =B45/C45*100 -> 35.492165
A46: AF420MJ | B46: 4612.51 | C46: 13537 | D46: =B46/C46*100 -> 34.073355
A47: AF427QV | B47: 4125.38 | C47: 12267 | D47: =B47/C47*100 -> 33.629901
A48: AF553MI | B48: 5375.01 | C48: 16014 | D48: =B48/C48*100 -> 33.564444
... A61: AG391BA | B61: 4758.42 | C61: 13638 | D61: =B61/C61*100 -> 34.890893
A62: AG391BB | B62: 0 | C62: 0
A63: AG391BC | B63: 6539.27 | C63: 17374 | D63: =B63/C63*100 -> 37.638253
A64: AG478GO | B64: 5382.4 | C64: 15586 | D64: =B64/C64*100 -> 34.533556
A65: AG735JK | B65: 5500.02 | C65: 15735 | D65: =B65/C65*100 -> 34.954051
A66: AG735JL | B66: 7167.4 | C66: 20793 | D66: =B66/C66*100 -> 34.470254
A67: AG812AM | B67: 5115.45 | C67: 14059 | D67: =B67/C67*100 -> 36.385589
A68: AG767YX | B68: 5342.25 | C68: 14332 | D68: =B68/C68*100 -> 37.274979
A69: AG920EX | B69: 1302.09 | C69: 3509 | D69: =B69/C69*100 -> 37.107153
A70: AG942BJ | B70: 0 | C70: 0
A71: FMO441 | B71: 3918.9 | C71: 10472 | D71: =B71/C71*100 -> 37.422651
A72: KHY272 | B72: 6283.53 | C72: 16814 | D72: =B72/C72*100 -> 37.370822
...

Sheet ENERO 2025
A1: Promedio combustible mes Enero 2025
A4: Unidad | B4: Litros | C4: Kms | D4: Promedio
A5: AA129CZ | B5: 2295 | C5: 5318 | D5: =B5/C5*100 -> 43.155322
A6: AA850LE | B6: 5853.8 | C6: 14585 | D6: =B6/C6*100 -> 40.135756
A7: AB398KK
A8: AB398KL
A9: AB475SV | B9: 3830 | C9: 10169 | D9: =B9/C9*100 -> 37.663487
A10: AB475SX | B10: 5559.2 | C10: 14796 | D10: =B10/C10*100 -> 37.572317
A11: AB475SZ | B11: 5098 | C11: 12680 | D11: =B11/C11*100 -> 40.205047
A12: AB475TG | B12: 5284.8 | C12: 14437 | D12: =B12/C12*100 -> 36.605943
A13: AB475TH | B13: 2491 | C13: 6842 | D13: =B13/C13*100 -> 36.407483
A14: AB475TI | B14: 6408 | C14: 17511 | D14: =B14/C14*100 -> 36.594141
A15: AB475TJ | B15: 6548 | C15: 18254 | D15: =B15/C15*100 -> 35.87159
A16: AC488KH | B16: 3922 | C16: 11804 | D16: =B16/C16*100 -> 33.226025
A17: AC576YK | B17: 6440 | C17: 17388 | D17: =B17/C17*100 -> 37.037037
A18: AC576YL | B18: 4432 | C18: 11987 | D18: =B18/C18*100 -> 36.973388
A19: AC576YM | B19: 5816 | C19: 16273 | D19: =B19/C19*100 -> 35.740183
A20: AC576YN | B20: 5723 | C20: 14943 | D20: =B20/C20*100 -> 38.298869
... A69: AG920EX | B69: 7119 | C69: 19969 | D69: =B69/C69*100 -> 35.650258
A70: AG960XE
A71: AG960XF
A72: AG942BJ | B72: 5424 | C72: 14533 | D72: =B72/C72*100 -> 37.321957
A73: FMO441
A74: KHY272 | B74: 6081.17 | C74: 16869 | D74: =B74/C74*100 -> 36.049381
A75: LDJ115 | B75: 4330.41 | C75: 11264 | D75: =B75/C75*100 -> 38.444691
A76: LIQ701 | B76: 7007 | C76: 19615 | D76: =B76/C76*100 -> 35.722661
A77: LIQ702 | B77: 5867.97 | C77: 14317 | D77: =B77/C77*100 -> 40.986031
A78: LLA868 | B78: 5096 | C78: 12461 | D78: =B78/C78*100 -> 40.895594
A79: LLA869 | B79: 4869 | C79: 11558 | D79: =B79/C79*100 -> 42.126666
A80: LLN460 | B80: 5686 | C80: 14393 | D80: =B80/C80*100 -> 39.505315
A81: LLN461 | B81: 4660 | C81: 11600 | D81: =B81/C81*100 -> 40.172414
A82: LLN462 | B82: 8686 | C82: 21748 | D82: =B82/C82*100 -> 39.939305
A83: LLN463 | B83: 3284 | C83: 8505 | D83: =B83/C83*100 -> 38.612581
A84: LTL641 | B84: 5356 | C84: 14340 | D84: =B84/C84*100 -> 37.35007
A85: MIA865 | B85: 6359.63 | C85: 18340 | D85: =B85/C85*100 -> 34.676281
A86: MKQ926 | B86: 5717.9 | C86: 16051 | D86: =B86/C86*100 -> 35.623326
A87: MRI892
A88: NNF283 | B88: 4600 | C88: 12713 | D88: =B88/C88*100 -> 36.183434
A89: NNF469 | B89: 6103 | C89: 16604 | D89: =B89/C89*100 -> 36.756203
A90: NVX521 | B90: 4358 | C90: 11452 | D90: =B90/C90*100 -> 38.054488
...

Sheet FEBRERO 2025
A1: Promedio combustible mes FEBRERO 2025
A4: Unidad | B4: Litros | C4: Kms | D4: Promedio
A5: AA129CZ | B5: 7038.59 | C5: 17623 | D5: =B5/C5*100 -> 39.939795
A6: AA850LE | B6: 5861.2 | C6: 14218 | D6: =B6/C6*100 -> 41.223801
A7: AB398KK
A8: AB398KL
A9: AB475SV | B9: 7489 | C9: 19697 | D9: =B9/C9*100 -> 38.021018
A10: AB475SX | B10: 5468.88 | C10: 14600 | D10: =B10/C10*100 -> 37.458082
A11: AB475SZ | B11: 7566.97 | C11: 20159 | D11: =B11/C11*100 -> 37.536435
A12: AB475TG | B12: 6488.62 | C12: 17426 | D12: =B12/C12*100 -> 37.235281
A13: AB475TH | B13: 5220.77 | C13: 14568 | D13: =B13/C13*100 -> 35.837246
A14: AB475TI | B14: 3927 | C14: 10992 | D14: =B14/C14*100 -> 35.725983
A15: AB475TJ | B15: 4821 | C15: 13317 | D15: =B15/C15*100 -> 36.201847
A16: AC488KH | B16: 5116.73 | C16: 15397 | D16: =B16/C16*100 -> 33.231993
A17: AC576YK | B17: 6271.41 | C17: 17262 | D17: =B17/C17*100 -> 36.330726
A18: AC576YL | B18: 6544.96 | C18: 17433 | D18: =B18/C18*100 -> 37.543509
A19: AC576YM | B19: 2146.06 | C19: 5916 | D19: =B19/C19*100 -> 36.275524
A20: AC576YN | B20: 6560 | C20: 16966 | D20: =B20/C20*100 -> 38.665566
... A43: AF304WT | B43: 4054.6 | C43: 10658 | D43: =B43/C43*100 -> 38.042785
A44: AF369FA
A45: AF371QB | B45: 5375.97 | C45: 15091 | D45: =B45/C45*100 -> 35.623683
A46: AF420MJ
A47: AF427QV | B47: 7269.29 | C47: 20863 | D47: =B47/C47*100 -> 34.842976
A48: AF553MI | B48: 7092.93 | C48: 19745 | D48: =B48/C48*100 -> 35.922664
A49: AF639AH | B49: 8283.91 | C49: 21935 | D49: =B49/C49*100 -> 37.765717
A50: AF639AI | B50: 7917.13 | C50: 21682 | D50: =B50/C50*100 -> 36.514759
A51: AF639AJ | B51: 7090.91 | C51: 19348 | D51: =B51/C51*100 -> 36.649318
A52: AF839EW | B52: 5810.97 | C52: 16813 | D52: =B52/C52*100 -> 34.562362
A53: AG006FU | B53: 4378.76 | C53: 12340 | D53: =B53/C53*100 -> 35.484279
A54: AG006FV | B54: 5969.95 | C54: 16843 | D54: =B54/C54*100 -> 35.444695
A55: AG006FY | B55: 6381.74 | C55: 17826 | D55: =B55/C55*100 -> 35.80018
A56: AG235ER | B56: 4771.78 | C56: 12843 | D56: =B56/C56*100 -> 37.154715
A57: AG326PH | B57: 3980 | C57: 11837 | D57: =B57/C57*100 -> 33.623384
A58: AG326PT | B58: 4104.087 | C58: 11313 | D58: =B58/C58*100 -> 36.277619
... A71: AG960XF | B71: 4614.21 | C71: 13189 | D71: =B71/C71*100 -> 34.985291
A72: AG942BJ
A73: KHY272 | B73: 4967.88 | C73: 13020 | D73: =B73/C73*100 -> 38.15576
A74: LDJ115 | B74: 4571.21 | C74: 11668 | D74: =B74/C74*100 -> 39.177323
A75: LIQ701 | B75: 4740.34 | C75: 12760 | D75: =B75/C75*100 -> 37.15
A76: LIQ702 | B76: 7280.59 | C76: 18740 | D76: =B76/C76*100 -> 38.850534
...

Sheet MARZO 2025
A1: Promedio combustible mes MARZO 2025
A4: Unidad | B4: Litros | C4: Kms | D4: Promedio
A5: AA129CZ | B5: 4852.81 | C5: 12211 | D5: =B5/C5*100 -> 39.741299
A6: AA850LE | B6: 6548.7 | C6: 16053 | D6: =B6/C6*100 -> 40.794244
A7: AB398KK
A8: AB398KL
A9: AB475SV | B9: 5182.07 | C9: 14674 | D9: =B9/C9*100 -> 35.314638
A10: AB475SX | B10: 6453.25 | C10: 18164 | D10: =B10/C10*100 -> 35.527692
A11: AB475SZ | B11: 4331.06 | C11: 11646 | D11: =B11/C11*100 -> 37.18925
A12: AB475TG | B12: 4783.86 | C12: 12334 | D12: =B12/C12*100 -> 38.785958
A13: AB475TH | B13: 5296.83 | C13: 14226 | D13: =B13/C13*100 -> 37.233446
A14: AB475TI | B14: 6150.6 | C14: 17560 | D14: =B14/C14*100 -> 35.026196
A15: AB475TJ | B15: 4321.8 | C15: 12653 | D15: =B15/C15*100 -> 34.156327
A16: AC488KH | B16: 4470.09 | C16: 12391 | D16: =B16/C16*100 -> 36.075297
A17: AC576YK | B17: 6397.12 | C17: 17041 | D17: =B17/C17*100 -> 37.539581
A18: AC576YL | B18: 4329.44 | C18: 11037 | D18: =B18/C18*100 -> 39.226601
A19: AC576YM | B19: 2246.1 | C19: 6036 | D19: =B19/C19*100 -> 37.21173
A20: AC576YN | B20: 4953.48 | C20: 13122 | D20: =B20/C20*100 -> 37.749428
... A23: AC576ZN | B23: 4501.06 | C23: 12545 | D23: =B23/C23*100 -> 35.879314
A24: AE304JJ
A25: AE305CV | B25: 4894.58 | C25: 13874 | D25: =B25/C25*100 -> 35.278795
A26: AE361CW | B26: 4725.02 | C26: 12634 | D26: =B26/C26*100 -> 37.39924
A27: AE362RX | B27: 6496.35 | C27: 17397 | D27: =B27/C27*100 -> 37.341783
A28: AE362RY | B28: 5672.84 | C28: 14308 | D28: =B28/C28*100 -> 39.648029
A29: AE379FQ | B29: 4908.23 | C29: 13531 | D29: =B29/C29*100 -> 36.273963
A30: AE418OT | B30: 6397.88 | C30: 17724 | D30: =B30/C30*100 -> 36.097269
A31: AE418OU | B31: 5137.96 | C31: 14539 | D31: =B31/C31*100 -> 35.339157
A32: AE450BO | B32: 7548.15 | C32: 22272 | D32: =B32/C32*100 -> 33.89076
A33: AE629VP | B33: 6436.67 | C33: 17114 | D33: =B33/C33*100 -> 37.610553
A34: AE814AC | B34: 5618.63 | C34: 15601 | D34: =B34/C34*100 -> 36.01455
A35: AE887HJ | B35: 2696.41 | C35: 8186 | D35: =B35/C35*100 -> 32.939287
A36: AE887HK | B36: 6965.76 | C36: 19078 | D36: =B36/C36*100 -> 36.512003
... A45: AF371QB | B45: 5303.25 | C45: 15938 | D45: =B45/C45*100 -> 33.27425
A46: AF420MJ
A47: AF427QV | B47: 7133.4 | C47: 20657 | D47: =B47/C47*100 -> 34.532604
A48: AF553MI | B48: 3692.56 | C48: 10910 | D48: =B48/C48*100 -> 33.845646
A49: AF639AH | B49: 4806.18 | C49: 12553 | D49: =B49/C49*100 -> 38.287103
A50: AF639AI | B50: 7467.09 | C50: 21858 | D50: =B50/C50*100 -> 34.161817
A51: AF639AJ | B51: 7262.45 | C51: 21158 | D51: =B51/C51*100 -> 34.324842
A52: AF839EW | B52: 6030.56 | C52: 17996 | D52: =B52/C52*100 -> 33.510558
...

Sheet ABRIL 2025
A1: Promedio combustible mes ABRIL 2025
A4: Unidad | B4: Litros | C4: Kms | D4: Promedio
A5: AA129CZ | B5: 4487.34 | C5: 10711 | D5: =B5/C5*100 -> 41.894688
A6: AA850LE | B6: 5573.15 | C6: 14805 | D6: =B6/C6*100 -> 37.643701
A7: AB475SX | B7: 6180.58 | C7: 17549 | D7: =B7/C7*100 -> 35.218987
A8: AB475SZ | B8: 6675.84 | C8: 18285 | D8: =B8/C8*100 -> 36.509926
A9: AB475TG | B9: 5071.89 | C9: 13249 | D9: =B9/C9*100 -> 38.281304
A10: AB475TH | B10: 3064.91 | C10: 8318 | D10: =B10/C10*100 -> 36.846718
A11: AB475TI | B11: 3286.95 | C11: 8800 | D11: =B11/C11*100 -> 37.351705
A12: AB475TJ | B12: 4471.73 | C12: 12163 | D12: =B12/C12*100 -> 36.765025
A13: AB475SV | B13: 3079.44 | C13: 7739 | D13: =B13/C13*100 -> 39.791187
A14: AC576YN | B14: 5577.34 | C14: 15629 | D14: =B14/C14*100 -> 35.68584
A15: AC488KH | B15: 2711.89 | C15: 7890 | D15: =B15/C15*100 -> 34.371229
A16: AC576YK | B16: 6645.85 | C16: 18194 | D16: =B16/C16*100 -> 36.527701
... A105: PNH473 | B105: 6611.95 | C105: 16533 | D105: =B105/C105*100 -> 39.992439
A106: Total general | B106: =SUM(B5:B105) -> 528719.04 | C106: =SUM(C5:C105) -> 1472914 | D106: =B106/C106*100 -> 35.896124

Sheet MAYO 2025
A1: Promedio combustible mes MAYO 2025
A4: Unidad | B4: Litros | C4: Kms | D4: Promedio
A5: AA129CZ | B5: 6175.61 | C5: 15203 | D5: =B5/C5*100 -> 40.620996
A6: AA850LE | B6: 4721.95 | C6: 12935 | D6: =B6/C6*100 -> 36.505218
A7: AB475SX | B7: 6589.17 | C7: 18886 | D7: =B7/C7*100 -> 34.889177
A8: AB475SZ | B8: 3167 | C8: 8869 | D8: =B8/C8*100 -> 35.708648
A9: AB475TG | B9: 7660.09 | C9: 21776 | D9: =B9/C9*100 -> 35.176754
A10: AB475TH | B10: 1339.37 | C10: 3169 | D10: =B10/C10*100 -> 42.264752
A11: AB475TI | B11: 7962.88 | C11: 22312 | D11: =B11/C11*100 -> 35.688777
A12: AB475TJ | B12: 2975.34 | C12: 8519 | D12: =B12/C12*100 -> 34.92593
A13: AB475SV | B13: 1351.53 | C13: 3476 | D13: =B13/C13*100 -> 38.881761
A14: AC576YN | B14: 4526.7 | C14: 11291 | D14: =B14/C14*100 -> 40.091223
A15: AC488KH | B15: 5685.37 | C15: 16269 | D15: =B15/C15*100 -> 34.946032
A16: AC576YK | B16: 8225.14 | C16: 22220 | D16: =B16/C16*100 -> 37.016832
... A106: PNH473 | B106: 9698.67 | C106: 26802 | D106: =B106/C106*100 -> 36.186367
A107: Total general | B107: =SUM(B5:B106) -> 576189.17 | C107: =SUM(C5:C106) -> 1604566.6 | D107: =B107/C107*100 -> 35.909334

Sheet JUNIO 2025
A1: Promedio combustible mes JUNIO 2025
A4: Unidad | B4: Litros | C4: Kms | D4: Promedio
A5: AA129CZ | B5: 5317.85 | C5: 13971 | D5: =B5/C5*100 -> 38.063489
A6: AA850LE | B6: 5352.96 | C6: 14428 | D6: =B6/C6*100 -> 37.101192
A7: AB475SX | B7: 5119.32 | C7: 13348 | D7: =B7/C7*100 -> 38.352712
A8: AB475SZ | B8: 4284.31 | C8: 11781 | D8: =B8/C8*100 -> 36.366268
A9: AB475TG | B9: 6355.59 | C9: 17700 | D9: =B9/C9*100 -> 35.907288
A10: AB475TH | B10: 2502.45 | C10: 7022 | D10: =B10/C10*100 -> 35.637283
A11: AB475TI | B11: 5975.74 | C11: 16423 | D11: =B11/C11*100 -> 36.386409
A12: AB475TJ | B12: 5752.53 | C12: 16563 | D12: =B12/C12*100 -> 34.731208
A13: AB475SV | B13: 7208.66 | C13: 19833 | D13: =B13/C13*100 -> 36.346796
A14: AC576YN | B14: 4910.35 | C14: 13317 | D14: =B14/C14*100 -> 36.872794
A15: AC488KH | B15: 5488.34 | C15: 15531 | D15: =B15/C15*100 -> 35.337969
A16: AC576YK | B16: 8259.24 | C16: 21950 | D16: =B16/C16*100 -> 37.627517
... A107: PNH473 | B107: 6497.44 | C107: 17810 | D107: =B107/C107*100 -> 36.481976
A108: Total general | B108: =SUM(B5:B107) -> 593252.44 | C108: =SUM(C5:C107) -> 1649140 | D108: =B108/C108*100 -> 35.973443

Sheet JULIO 2025
A1: Promedio combustible mes JULIO 2025
A4: Unidad | B4: Litros | C4: Kms | D4: Promedio
A5: AA129CZ | B5: 8185.23 | C5: 20975 | D5: =B5/C5*100 -> 39.023743
A6: AA850LE | B6: 6100.07 | C6: 15917 | D6: =B6/C6*100 -> 38.324245
A7: AB475SX | B7: 5707.72 | C7: 16108 | D7: =B7/C7*100 -> 35.43407
A8: AB475SZ | B8: 7175.34 | C8: 19123 | D8: =B8/C8*100 -> 37.522042
A9: AB475TG | B9: 3269.7 | C9: 8941 | D9: =B9/C9*100 -> 36.569735
A10: AB475TH | B10: 6212.15 | C10: 16177 | D10: =B10/C10*100 -> 38.401125
A11: AB475TI | B11: 6849.65 | C11: 18551 | D11: =B11/C11*100 -> 36.923346
A12: AB475TJ | B12: 6721.89 | C12: 19817 | D12: =B12/C12*100 -> 33.919816
A13: AB475SV | B13: 6970.08 | C13: 19164 | D13: =B13/C13*100 -> 36.370695
A14: AC576YN | B14: 7413.37 | C14: 19729 | D14: =B14/C14*100 -> 37.576005
A15: AC488KH | B15: 5885.71 | C15: 17367 | D15: =B15/C15*100 -> 33.890194
A16: AC576YK | B16: 8779.87 | C16: 24276 | D16: =B16/C16*100 -> 36.166873
... A76: LIQ701 | B76: 4923.25 | C76: 13173 | D76: =B76/C76*100 -> 37.373795
A77: LIQ702 | B77: 5183.72 | C77: 9542 | D77: 34.33
A78: LLA868 | B78: 5085.25 | C78: 13072 | D78: =B78/C78*100 -> 38.901851
A79: LLA869 | B79: 7366.43 | C79: 18810 | D79: =B79/C79*100 -> 39.162307
A80: LLN460 | B80: 7449.51 | C80: 17948 | D80: =B80/C80*100 -> 41.506073
A81: LLN461 | B81: 7395.12 | C81: 20008 | D81: =B81/C81*100 -> 36.960816
A82: LLN462 | B82: 6994.39 | C82: 19918 | D82: =B82/C82*100 -> 35.115925
A83: LLN463 | B83: 3074.78 | C83: 8160 | D83: =B83/C83*100 -> 37.681127
A84: LTL641 | B84: 6452.12 | C84: 18733 | D84: =B84/C84*100 -> 34.442535
A85: MIA865 | B85: 7266.46 | C85: 21088 | D85: =B85/C85*100 -> 34.457796
A86: MKQ926 | B86: 5557.82 | C86: 15769 | D86: =B86/C86*100 -> 35.245228
A87: MRI892 | B87: 4628.49 | C87: 11619 | D87: =B87/C87*100 -> 39.835528
A88: NNF283 | B88: 7669.87 | C88: 20743 | D88: =B88/C88*100 -> 36.975703
A89: NNF469 | B89: 6435.86 | C89: 18293 | D89: =B89/C89*100 -> 35.182092
... A108: PNH473 | B108: 6050.88 | C108: 16542 | D108: =B108/C108*100 -> 36.57889
A109: Total general | B109: =SUM(B8:B108) -> 668268.35 | C109: =SUM(C8:C108) -> 1841948 | D109: =B109/C109*100 -> 36.280522

Sheet AGOSTO 2025
A1: PromediocombustiblemesAGOSTO2025
A4: Unidad | B4: Litros | C4: Kms | D4: Promedio
A5: AA129CZ | B5: 7036.59 | C5: 18628 | D5: =B5/C5*100 -> 37.774265
A6: AA850LE | B6: 5873.76 | C6: 16017 | D6: =B6/C6*100 -> 36.672036
A7: AB475SZ | B7: 6566.15 | C7: 18396 | D7: =B7/C7*100 -> 35.693357
A8: AB475TG | B8: 7044.64 | C8: 20259 | D8: =B8/C8*100 -> 34.772891
A9: AB475TH | B9: 6377.52 | C9: 16733 | D9: =B9/C9*100 -> 38.113429
A10: AB475TI | B10: 6897.43 | C10: 19752 | D10: =B10/C10*100 -> 34.92016
A11: AB475TJ | B11: 6257.06 | C11: 18714 | D11: =B11/C11*100 -> 33.435182
A12: AB475SV | B12: 6509.46 | C12: 16356 | D12: =B12/C12*100 -> 39.798606
A13: AC576YN | B13: 5839.74 | C13: 15457 | D13: =B13/C13*100 -> 37.780553
A14: AC488KH | B14: 7102.12 | C14: 21204.63 | D14: =B14/C14*100 -> 33.493251
A15: AC576YK | B15: 5751.91 | C15: 15975 | D15: =B15/C15*100 -> 36.005696
A16: AC576YL | B16: 5399.22 | C16: 14292 | D16: =B16/C16*100 -> 37.777918
... A108: Totalgeneral | B108: 600690.87 | C108: 1660216.3 | D108: =B108/C108*100 -> 36.181483

Sheet SEPTIEMBRE 2025
A1: Promediocombustiblemes Septiembre2025
A4: Unidad | B4: Litros | C4: Kms | D4: Promedio
A5: AA129CZ | B5: 5643.94 | C5: 14206 | D5: =B5/C5*100 -> 39.729269
A6: AA850LE | B6: 6158.58 | C6: 16025 | D6: =B6/C6*100 -> 38.431076
A7: AB475SX | B7: 8488.18 | C7: 23471 | D7: =B7/C7*100 -> 36.164543
A8: AB475SZ | B8: 6373.2 | C8: 17768 | D8: =B8/C8*100 -> 35.868978
A9: AB475TG | B9: 4106.38 | C9: 11619 | D9: =B9/C9*100 -> 35.34194
A10: AB475TH | B10: 4431.09 | C10: 12094 | D10: =B10/C10*100 -> 36.638746
A11: AB475TI | B11: 3884.29 | C11: 10636 | D11: =B11/C11*100 -> 36.520214
A12: AB475TJ | B12: 5368.95 | C12: 16070 | D12: =B12/C12*100 -> 33.40977
A13: AB475SV | B13: 4509.19 | C13: 11197 | D13: =B13/C13*100 -> 40.271412
A14: AC576YN | B14: 2588.87 | C14: 7513 | D14: =B14/C14*100 -> 34.458539
A15: AC488KH | B15: 7695.81 | C15: 21814 | D15: =B15/C15*100 -> 35.279224
A16: AC576YK | B16: 5381.05 | C16: 14801 | D16: =B16/C16*100 -> 36.355989
... A113: Total general | B113: 559443.71 | C113: 1551730 | D113: =B113/C113*100 -> 36.052903

Sheet OCTUBRE 2025
A1: Promediocombustiblemes Octubre 2025
A4: Unidad | B4: Litros | C4: Kms | D4: Promedio
A5: AA129CZ | B5: 6458.54 | C5: 16401.81 | D5: =B5/C5*100 -> 39.376996
A6: AA850LE | B6: 3964.66 | C6: 11137 | D6: =B6/C6*100 -> 35.598994
A7: AB475SX | B7: 5749.87 | C7: 16057 | D7: =B7/C7*100 -> 35.809118
A8: AB475SZ | B8: 4460.13 | C8: 12287 | D8: =B8/C8*100 -> 36.299585
A9: AB475TG | B9: 6263.17 | C9: 17700 | D9: =B9/C9*100 -> 35.385141
A10: AB475TH | B10: 5914.27 | C10: 15827 | D10: =B10/C10*100 -> 37.368232
A11: AB475TI | B11: 6770.56 | C11: 19099 | D11: =B11/C11*100 -> 35.449814
A12: AB475TJ | B12: 6205.43 | C12: 17490 | D12: =B12/C12*100 -> 35.479874
A13: AB475SV | B13: 5259.7 | C13: 13205 | D13: =B13/C13*100 -> 39.831125
A14: AC576YN | B14: 6636.24 | C14: 17413 | D14: =B14/C14*100 -> 38.110837
A15: AC488KH | B15: 5550.77 | C15: 16831 | D15: =B15/C15*100 -> 32.979443
A16: AC576YK | B16: 5713.93 | C16: 15618 | D16: =B16/C16*100 -> 36.585542
... A115: PNH473 | B115: 6210.37 | C115: 16208 | D115: =B115/C115*100 -> 38.316695
A116: Total general | B116: 661124.46 | C116: =SUM(C5:C115) -> 1849460 | D116: =B116/C116*100 -> 35.746892

Sheet CONSOLIDADO
B2: PATENTE | C2: patente2 | D2: 45413 | E2: 45444 | F2: 45474 | G2: 45505 | H2: 45536 | I2: 45566 | J2: 45597 | K2: 45627 | L2: 45658 | M2: 45689 | N2: 45717 | O2: 45748 | P2: 45778 | Q2: 45809 | R2: 45839 | S2: 45870 | T2: 45901 | U2: 45931
A3: 36 / 37 | B3: OIX583 | C3: IVECO 330 | D3: =VLOOKUP(Tabla3[[#This Row],[PATENTE]],'MAYO 2024'!$A:$D,4,0) -> 41.227537 | E3: =VLOOKUP(Tabla3[[#This Row],[PATENTE]],'JUNIO 2024'!$A:$D,4,0) -> 41.632936 | F3: =VLOOKUP(Tabla3[[#This Row],[PATENTE]],'JULIO 2024'!$A:$D,4,0) -> 41.812196 | G3: =VLOOKUP(Tabla3[[#This Row],[PATENTE]],'AGOSTO 2024'!$A:$D,4,0) -> 42.230776 | I3: =VLOOKUP(Tabla3[[#This Row],[PATENTE]],'OCTUBRE 2024'!$A:$D,4,0) -> 40.124393 | J3: =VLOOKUP(Tabla3[[#This Row],[PATENTE]],'NOVIEMBRE 2024'!$A:$D,4,0) -> 40.634073 | K3: =VLOOKUP(Tabla3[[#This Row],[PATENTE]],'DICIEMBRE 2024'!$A:$D,4,0) -> 39.987104 | L3: =VLOOKUP(Tabla3[[#This Row],[PATENTE]],'ENERO 2025'!$A:$D,4,0) -> 38.473164 | M3: =VLOOKUP(Tabla3[[#This Row],[PATENTE]],'FEBRERO 2025'!$A:$D,4,0) -> 40.715915 | N3: =VLOOKUP(Tabla3[[#This Row],[PATENTE]],'MARZO 2025'!$A:$D,4,0) -> 40.672855 | O3: =VLOOKUP(Tabla3[[#This Row],[PATENTE]],'ABRIL 2025'!$A:$D,4,0) -> 37.024559 | P3: =VLOOKUP(Tabla3[[#This Row],[PATENTE]],'MAYO 2025'!$A:$D,4,0) -> 36.39295 | Q3: =VLOOKUP(Tabla3[[#This Row],[PATENTE]],'JUNIO 2025'!$A:$D,4,0) -> 38.61518 | R3: =VLOOKUP(Tabla3[[#This Row],[PATENTE]],'JULIO 2025'!$A:$D,4,0) -> 39.128999 | S3: =VLOOKUP(Tabla3[[#This Row],[PATENTE]],'AGOSTO 2025'!$A:$D,4,0) -> 40.222669 | T3: =VLOOKUP(Tabla3[[#This Row],[PATENTE]],'SEPTIEMBRE 2025'!$A:$D,4,0) -> 38.499773 | U3: =VLOOKUP(Tabla3[[#This Row],[PATENTE]],'OCTUBRE 2025'!$A:$D,4,0) -> 38.563202 | V3: =AVERAGE(D3:U3) -> 39.762252
B4: MRI892 | C4: IVECO 330 | D4: =VLOOKUP(Tabla3[[#This Row],[PATENTE]],'MAYO 2024'!$A:$D,4,0) -> 36.013939 | E4: =VLOOKUP(Tabla3[[#This Row],[PATENTE]],'JUNIO 2024'!$A:$D,4,0) -> 38.747538 | F4: =VLOOKUP(Tabla3[[#This Row],[PATENTE]],'JULIO 2024'!$A:$D,4,0) -> 40.230616 | G4: =VLOOKUP(Tabla3[[#This Row],[PATENTE]],'AGOSTO 2024'!$A:$D,4,0) -> 40.32526 | H4: =VLOOKUP(Tabla3[[#This Row],[PATENTE]],'SEPTIEMBRE 2024'!$A:$D,4,0) -> 39.563115 | I4: =VLOOKUP(Tabla3[[#This Row],[PATENTE]],'OCTUBRE 2024'!$A:$D,4,0) -> 39.761499 | J4: =VLOOKUP(Tabla3[[#This Row],[PATENTE]],'NOVIEMBRE 2024'!$A:$D,4,0) -> 39.2266 | K4: =VLOOKUP(Tabla3[[#This Row],[PATENTE]],'DICIEMBRE 2024'!$A:$D,4,0) -> 40.667546 | P4: =VLOOKUP(Tabla3[[#This Row],[PATENTE]],'MAYO 2025'!$A:$D,4,0) -> 39.397391 | Q4: =VLOOKUP(Tabla3[[#This Row],[PATENTE]],'JUNIO 2025'!$A:$D,4,0) -> 37.222058 | R4: =VLOOKUP(Tabla3[[#This Row],[PATENTE]],'JULIO 2025'!$A:$D,4,0) -> 39.835528 | S4: =VLOOKUP(Tabla3[[#This Row],[PATENTE]],'AGOSTO 2025'!$A:$D,4,0) -> 39.622011 | T4: =VLOOKUP(Tabla3[[#This Row],[PATENTE]],'SEPTIEMBRE 2025'!$A:$D,4,0) -> 40.314245 | U4: =VLOOKUP(Tabla3[[#This Row],[PATENTE]],'OCTUBRE 2025'!$A:$D,4,0) -> 39.86642 | V4: =AVERAGE(D4:U4) -> 39.342412
B5: LDJ115 | C5: IVECO 330 | D5: =VLOOKUP(Tabla3[[#This Row],[PATENTE]],'MAYO 2024'!$A:$D,4,0) -> 37.523245 | E5: =VLOOKUP(Tabla3[[#This Row],[PATENTE]],'JUNIO 2024'!$A:$D,4,0) -> 39.604459 | F5: =VLOOKUP(Tabla3[[#This Row],[PATENTE]],'JULIO 2024'!$A:$D,4,0) -> 40.293501 | G5: =VLOOKUP(Tabla3[[#This Row],[PATENTE]],'AGOSTO 2024'!$A:$D,4,0) -> 39.346109 | H5: =VLOOKUP(Tabla3[[#This Row],[PATENTE]],'SEPTIEMBRE 2024'!$A:$D,4,0) -> 39.155348 | I5: =VLOOKUP(Tabla3[[#This Row],[PATENTE]],'OCTUBRE 2024'!$A:$D,4,0) -> 38.697325 | J5: =VLOOKUP(Tabla3[[#This Row],[PATENTE]],'NOVIEMBRE 2024'!$A:$D,4,0) -> 38.971972 | K5: =VLOOKUP(Tabla3[[#This Row],[PATENTE]],'DICIEMBRE 2024'!$A:$D,4,0) -> 40.786081 | L5: =VLOOKUP(Tabla3[[#This Row],[PATENTE]],'ENERO 2025'!$A:$D,4,0) -> 38.444691 | M5: =VLOOKUP(Tabla3[[#This Row],[PATENTE]],'FEBRERO 2025'!$A:$D,4,0) -> 39.177323 | N5: =VLOOKUP(Tabla3[[#This Row],[PATENTE]],'MARZO 2025'!$A:$D,4,0) -> 40.133002 | O5: =VLOOKUP(Tabla3[[#This Row],[PATENTE]],'ABRIL 2025'!$A:$D,4,0) -> 37.104345 | P5: =VLOOKUP(Tabla3[[#This Row],[PATENTE]],'MAYO 2025'!$A:$D,4,0) -> 40.025606 | Q5: =VLOOKUP(Tabla3[[#This Row],[PATENTE]],'JUNIO 2025'!$A:$D,4,0) -> 41.142265 | R5: =VLOOKUP(Tabla3[[#This Row],[PATENTE]],'JULIO 2025'!$A:$D,4,0) -> 40.985979 | S5: =VLOOKUP(Tabla3[[#This Row],[PATENTE]],'AGOSTO 2025'!$A:$D,4,0) -> 37.239894 | T5: =VLOOKUP(Tabla3[[#This Row],[PATENTE]],'SEPTIEMBRE 2025'!$A:$D,4,0) -> 37.460213 | U5: =VLOOKUP(Tabla3[[#This Row],[PATENTE]],'OCTUBRE 2025'!$A:$D,4,0) -> 38.580129 | V5: =AVERAGE(D5:U5) -> 39.148416
B6: LLN461 | C6: IVECO 330 | D6: =VLOOKUP(Tabla3[[#This Row],[PATENTE]],'MAYO 2024'!$A:$D,4,0) -> 39.704892 | E6: =VLOOKUP(Tabla3[[#This Row],[PATENTE]],'JUNIO 2024'!$A:$D,4,0) -> 38.976587 | F6: =VLOOKUP(Tabla3[[#This Row],[PATENTE]],'JULIO 2024'!$A:$D,4,0) -> 39.544957 | G6: =VLOOKUP(Tabla3[[#This Row],[PATENTE]],'AGOSTO 2024'!$A:$D,4,0) -> 40.620033 | H6: =VLOOKUP(Tabla3[[#This Row],[PATENTE]],'SEPTIEMBRE 2024'!$A:$D,4,0) -> 42.280272 | I6: =VLOOKUP(Tabla3[[#This Row],[PATENTE]],'OCTUBRE 2024'!$A:$D,4,0) -> 42.733023 | J6: =VLOOKUP(Tabla3[[#This Row],[PATENTE]],'NOVIEMBRE 2024'!$A:$D,4,0) -> 43.274686 | K6: =VLOOKUP(Tabla3[[#This Row],[PATENTE]],'DICIEMBRE 2024'!$A:$D,4,0) -> 40.665756 | L6: =VLOOKUP(Tabla3[[#This Row],[PATENTE]],'ENERO 2025'!$A:$D,4,0) -> 40.172414 | M6: =VLOOKUP(Tabla3[[#This Row],[PATENTE]],'FEBRERO 2025'!$A:$D,4,0) -> 39.275005 | N6: =VLOOKUP(Tabla3[[#This Row],[PATENTE]],'MARZO 2025'!$A:$D,4,0) -> 37.685932 | O6: =VLOOKUP(Tabla3[[#This Row],[PATENTE]],'ABRIL 2025'!$A:$D,4,0) -> 33.304015 | P6: =VLOOKUP(Tabla3[[#This Row],[PATENTE]],'MAYO 2025'!$A:$D,4,0) -> 37.300386 | Q6: =VLOOKUP(Tabla3[[#This Row],[PATENTE]],'JUNIO 2025'!$A:$D,4,0) -> 37.427342 | R6: =VLOOKUP(Tabla3[[#This Row],[PATENTE]],'JULIO 2025'!$A:$D,4,0) -> 36.960816 | S6: =VLOOKUP(Tabla3[[#This Row],[PATENTE]],'AGOSTO 2025'!$A:$D,4,0) -> 33.989384 | T6: =VLOOKUP(Tabla3[[#This Row],[PATENTE]],'SEPTIEMBRE 2025'!$A:$D,4,0) -> 35.11888 | U6: =VLOOKUP(Tabla3[[#This Row],[PATENTE]],'OCTUBRE 2025'!$A:$D,4,0) -> 37.953239 | V6: =AVERAGE(D6:U6) -> 38.721534
B7: LLA868 | C7: IVECO 330 | D7: =VLOOKUP(Tabla3[[#This Row],[PATENTE]],'MAYO 2024'!$A:$D,4,0) -> 38.797221 | E7: =VLOOKUP(Tabla3[[#This Row],[PATENTE]],'JUNIO 2024'!$A:$D,4,0) -> 38.480925 | F7: =VLOOKUP(Tabla3[[#This Row],[PATENTE]],'JULIO 2024'!$A:$D,4,0) -> 40.825025 | G7: =VLOOKUP(Tabla3[[#This Row],[PATENTE]],'AGOSTO 2024'!$A:$D,4,0) -> 41.442874 | H7: =VLOOKUP(Tabla3[[#This Row],[PATENTE]],'SEPTIEMBRE 2024'!$A:$D,4,0) -> 41.427128 | I7: =VLOOKUP(Tabla3[[#This Row],[PATENTE]],'OCTUBRE 2024'!$A:$D,4,0) -> 39.200602 | J7: =VLOOKUP(Tabla3[[#This Row],[PATENTE]],'NOVIEMBRE 2024'!$A:$D,4,0) -> 41.379919 | K7: =VLOOKUP(Tabla3[[#This Row],[PATENTE]],'DICIEMBRE 2024'!$A:$D,4,0) -> 42.599359 | L7: =VLOOKUP(Tabla3[[#This Row],[PATENTE]],'ENERO 2025'!$A:$D,4,0) -> 40.895594 | M7: =VLOOKUP(Tabla3[[#This Row],[PATENTE]],'FEBRERO 2025'!$A:$D,4,0) -> 40.918128 | N7: =VLOOKUP(Tabla3[[#This Row],[PATENTE]],'MARZO 2025'!$A:$D,4,0) -> 37.047753 | O7: =VLOOKUP(Tabla3[[#This Row],[PATENTE]],'ABRIL 2025'!$A:$D,4,0) -> 39.489523 | P7: =VLOOKUP(Tabla3[[#This Row],[PATENTE]],'MAYO 2025'!$A:$D,4,0) -> 38.756575 | Q7: =VLOOKUP(Tabla3[[#This Row],[PATENTE]],'JUNIO 2025'!$A:$D,4,0) -> 38.61777 | R7: =VLOOKUP(Tabla3[[#This Row],[PATENTE]],'JULIO 2025'!$A:$D,4,0) -> 38.901851 | S7: =VLOOKUP(Tabla3[[#This Row],[PATENTE]],'AGOSTO 2025'!$A:$D,4,0) -> 39.046351 | T7: =VLOOKUP(Tabla3[[#This Row],[PATENTE]],'SEPTIEMBRE 2025'!$A:$D,4,0) -> 39.229203 | U7: =VLOOKUP(Tabla3[[#This Row],[PATENTE]],'OCTUBRE 2025'!$A:$D,4,0) -> 37.321388 | V7: =AVERAGE(D7:U7) -> 39.687622
B8: LLN462 | C8: IVECO 330 | D8: =VLOOKUP(Tabla3[[#This Row],[PATENTE]],'MAYO 2024'!$A:$D,4,0) -> 39.106583 | E8: =VLOOKUP(Tabla3[[#This Row],[PATENTE]],'JUNIO 2024'!$A:$D,4,0) -> 39.72457 | F8: =VLOOKUP(Tabla3[[#This Row],[PATENTE]],'JULIO 2024'!$A:$D,4,0) -> 38.319101 | G8: =VLOOKUP(Tabla3[[#This Row],[PATENTE]],'AGOSTO 2024'!$A:$D,4,0) -> 38.77127 | H8: =VLOOKUP(Tabla3[[#This Row],[PATENTE]],'SEPTIEMBRE 2024'!$A:$D,4,0) -> 40.581412 | I8: =VLOOKUP(Tabla3[[#This Row],[PATENTE]],'OCTUBRE 2024'!$A:$D,4,0) -> 39.827292 | J8: =VLOOKUP(Tabla3[[#This Row],[PATENTE]],'NOVIEMBRE 2024'!$A:$D,4,0) -> 40.126611 | K8: =VLOOKUP(Tabla3[[#This Row],[PATENTE]],'DICIEMBRE 2024'!$A:$D,4,0) -> 39.903888 | L8: =VLOOKUP(Tabla3[[#This Row],[PATENTE]],'ENERO 2025'!$A:$D,4,0) -> 39.939305 | M8: =VLOOKUP(Tabla3[[#This Row],[PATENTE]],'FEBRERO 2025'!$A:$D,4,0) -> 39.528595 | N8: =VLOOKUP(Tabla3[[#This Row],[PATENTE]],'MARZO 2025'!$A:$D,4,0) -> 36.541704 | O8: =VLOOKUP(Tabla3[[#This Row],[PATENTE]],'ABRIL 2025'!$A:$D,4,0) -> 34.592233 | P8: =VLOOKUP(Tabla3[[#This Row],[PATENTE]],'MAYO 2025'!$A:$D,4,0) -> 38.012186 | Q8: =VLOOKUP(Tabla3[[#This Row],[PATENTE]],'JUNIO 2025'!$A:$D,4,0) -> 42.215983 | R8: =VLOOKUP(Tabla3[[#This Row],[PATENTE]],'JULIO 2025'!$A:$D,4,0) -> 35.115925 | S8: =VLOOKUP(Tabla3[[#This Row],[PATENTE]],'AGOSTO 2025'!$A:$D,4,0) -> 34.930512 | T8: =VLOOKUP(Tabla3[[#This Row],[PATENTE]],'SEPTIEMBRE 2025'!$A:$D,4,0) -> 36.534364 | V8: =AVERAGE(D8:U8) -> 38.457149
B9: LLN460 | C9: IVECO 330 | D9: =VLOOKUP(Tabla3[[#This Row],[PATENTE]],'MAYO 2024'!$A:$D,4,0) -> 40.39384 | E9: =VLOOKUP(Tabla3[[#This Row],[PATENTE]],'JUNIO 2024'!$A:$D,4,0) -> 40.78669 | F9: =VLOOKUP(Tabla3[[#This Row],[PATENTE]],'JULIO 2024'!$A:$D,4,0) -> 39.270163 | G9: =VLOOKUP(Tabla3[[#This Row],[PATENTE]],'AGOSTO 2024'!$A:$D,4,0) -> 40.861535 | H9: =VLOOKUP(Tabla3[[#This Row],[PATENTE]],'SEPTIEMBRE 2024'!$A:$D,4,0) -> 42.934693 | I9: =VLOOKUP(Tabla3[[#This Row],[PATENTE]],'OCTUBRE 2024'!$A:$D,4,0) -> 45.58789 | J9: =VLOOKUP(Tabla3[[#This Row],[PATENTE]],'NOVIEMBRE 2024'!$A:$D,4,0) -> 40.917713 | K9: =VLOOKUP(Tabla3[[#This Row],[PATENTE]],'DICIEMBRE 2024'!$A:$D,4,0) -> 40.722931 | L9: =VLOOKUP(Tabla3[[#This Row],[PATENTE]],'ENERO 2025'!$A:$D,4,0) -> 39.505315 | M9: =VLOOKUP(Tabla3[[#This Row],[PATENTE]],'FEBRERO 2025'!$A:$D,4,0) -> 40.228348 | N9: =VLOOKUP(Tabla3[[#This Row],[PATENTE]],'MARZO 2025'!$A:$D,4,0) -> 35.080848 | O9: =VLOOKUP(Tabla3[[#This Row],[PATENTE]],'ABRIL 2025'!$A:$D,4,0) -> 35.837776 | P9: =VLOOKUP(Tabla3[[#This Row],[PATENTE]],'MAYO 2025'!$A:$D,4,0) -> 40.000895 | Q9: =VLOOKUP(Tabla3[[#This Row],[PATENTE]],'JUNIO 2025'!$A:$D,4,0) -> 41.29604 | R9: =VLOOKUP(Tabla3[[#This Row],[PATENTE]],'JULIO 2025'!$A:$D,4,0) -> 41.506073 | S9: =VLOOKUP(Tabla3[[#This Row],[PATENTE]],'AGOSTO 2025'!$A:$D,4,0) -> 40.273411 | T9: =VLOOKUP(Tabla3[[#This Row],[PATENTE]],'SEPTIEMBRE 2025'!$A:$D,4,0) -> 42.053734 | V9: =AVERAGE(D9:U9) -> 40.426935
B10: AG006FY | C10: HEY ROAD | D10: =VLOOKUP(Tabla3[[#This Row],[PATENTE]],'MAYO 2024'!$A:$D,4,0) -> 36.863285 | E10: =VLOOKUP(Tabla3[[#This Row],[PATENTE]],'JUNIO 2024'!$A:$D,4,0) -> 35.505189 | F10: =VLOOKUP(Tabla3[[#This Row],[PATENTE]],'JULIO 2024'!$A:$D,4,0) -> 36.214442 | G10: =VLOOKUP(Tabla3[[#This Row],[PATENTE]],'AGOSTO 2024'!$A:$D,4,0) -> 35.436388 | H10: =VLOOKUP(Tabla3[[#This Row],[PATENTE]],'SEPTIEMBRE 2024'!$A:$D,4,0) -> 35.378217 | I10: =VLOOKUP(Tabla3[[#This Row],[PATENTE]],'OCTUBRE 2024'!$A:$D,4,0) -> 34.450602 | J10: =VLOOKUP(Tabla3[[#This Row],[PATENTE]],'NOVIEMBRE 2024'!$A:$D,4,0) -> 36.11688 | K10: =VLOOKUP(Tabla3[[#This Row],[PATENTE]],'DICIEMBRE 2024'!$A:$D,4,0) -> 35.743768 | L10: =VLOOKUP(Tabla3[[#This Row],[PATENTE]],'ENERO 2025'!$A:$D,4,0) -> 35.302364 | M10: =VLOOKUP(Tabla3[[#This Row],[PATENTE]],'FEBRERO 2025'!$A:$D,4,0) -> 35.80018 | N10: =VLOOKUP(Tabla3[[#This Row],[PATENTE]],'MARZO 2025'!$A:$D,4,0) -> 36.200808 | O10: =VLOOKUP(Tabla3[[#This Row],[PATENTE]],'ABRIL 2025'!$A:$D,4,0) -> 35.651885 | P10: =VLOOKUP(Tabla3[[#This Row],[PATENTE]],'MAYO 2025'!$A:$D,4,0) -> 35.277778 | Q10: =VLOOKUP(Tabla3[[#This Row],[PATENTE]],'JUNIO 2025'!$A:$D,4,0) -> 34.853479 | R10: =VLOOKUP(Tabla3[[#This Row],[PATENTE]],'JULIO 2025'!$A:$D,4,0) -> 34.24996 | S10: =VLOOKUP(Tabla3[[#This Row],[PATENTE]],'AGOSTO 2025'!$A:$D,4,0) -> 34.323814 | T10: =VLOOKUP(Tabla3[[#This Row],[PATENTE]],'SEPTIEMBRE 2025'!$A:$D,4,0) -> 34.309016 | U10: =VLOOKUP(Tabla3[[#This Row],[PATENTE]],'OCTUBRE 2025'!$A:$D,4,0) -> 34.232541 | V10: =AVERAGE(D10:U10) -> 35.328367
B11: AA129CZ | C11: IVECO 330 | D11: =VLOOKUP(Tabla3[[#This Row],[PATENTE]],'MAYO 2024'!$A:$D,4,0) -> 40.464371 | E11: =VLOOKUP(Tabla3[[#This Row],[PATENTE]],'JUNIO 2024'!$A:$D,4,0) -> 38.990504 | F11: =VLOOKUP(Tabla3[[#This Row],[PATENTE]],'JULIO 2024'!$A:$D,4,0) -> 39.903192 | G11: =VLOOKUP(Tabla3[[#This Row],[PATENTE]],'AGOSTO 2024'!$A:$D,4,0) -> 39.584849 | H11: =VLOOKUP(Tabla3[[#This Row],[PATENTE]],'SEPTIEMBRE 2024'!$A:$D,4,0) -> 39.350048 | I11: =VLOOKUP(Tabla3[[#This Row],[PATENTE]],'OCTUBRE 2024'!$A:$D,4,0) -> 39.564013 | J11: =VLOOKUP(Tabla3[[#This Row],[PATENTE]],'NOVIEMBRE 2024'!$A:$D,4,0) -> 38.769103 | K11: =VLOOKUP(Tabla3[[#This Row],[PATENTE]],'DICIEMBRE 2024'!$A:$D,4,0) -> 39.411085 | L11: =VLOOKUP(Tabla3[[#This Row],[PATENTE]],'ENERO 2025'!$A:$D,4,0) -> 43.155322 | M11: =VLOOKUP(Tabla3[[#This Row],[PATENTE]],'FEBRERO 2025'!$A:$D,4,0) -> 39.939795 | N11: =VLOOKUP(Tabla3[[#This Row],[PATENTE]],'MARZO 2025'!$A:$D,4,0) -> 39.741299 | O11: =VLOOKUP(Tabla3[[#This Row],[PATENTE]],'ABRIL 2025'!$A:$D,4,0) -> 41.894688 | P11: =VLOOKUP(Tabla3[[#This Row],[PATENTE]],'MAYO 2025'!$A:$D,4,0) -> 40.620996 | Q11: =VLOOKUP(Tabla3[[#This Row],[PATENTE]],'JUNIO 2025'!$A:$D,4,0) -> 38.063489 | R11: =VLOOKUP(Tabla3[[#This Row],[PATENTE]],'JULIO 2025'!$A:$D,4,0) -> 39.023743 | S11: =VLOOKUP(Tabla3[[#This Row],[PATENTE]],'AGOSTO 2025'!$A:$D,4,0) -> 37.774265 | T11: =VLOOKUP(Tabla3[[#This Row],[PATENTE]],'SEPTIEMBRE 2025'!$A:$D,4,0) -> 39.729269 | U11: =VLOOKUP(Tabla3[[#This Row],[PATENTE]],'OCTUBRE 2025'!$A:$D,4,0) -> 39.376996 | V11: =AVERAGE(D11:U11) -> 39.742057
B12: LLA869 | C12: IVECO 330 | D12: =VLOOKUP(Tabla3[[#This Row],[PATENTE]],'MAYO 2024'!$A:$D,4,0) -> 42.185282 | E12: =VLOOKUP(Tabla3[[#This Row],[PATENTE]],'JUNIO 2024'!$A:$D,4,0) -> 43.189095 | F12: =VLOOKUP(Tabla3[[#This Row],[PATENTE]],'JULIO 2024'!$A:$D,4,0) -> 42.335911 | G12: =VLOOKUP(Tabla3[[#This Row],[PATENTE]],'AGOSTO 2024'!$A:$D,4,0) -> 43.918533 | H12: =VLOOKUP(Tabla3[[#This Row],[PATENTE]],'SEPTIEMBRE 2024'!$A:$D,4,0) -> 43.254767 | I12: =VLOOKUP(Tabla3[[#This Row],[PATENTE]],'OCTUBRE 2024'!$A:$D,4,0) -> 44.58823 | J12: =VLOOKUP(Tabla3[[#This Row],[PATENTE]],'NOVIEMBRE 2024'!$A:$D,4,0) -> 41.367098 | K12: =VLOOKUP(Tabla3[[#This Row],[PATENTE]],'DICIEMBRE 2024'!$A:$D,4,0) -> 39.789666 | L12: =VLOOKUP(Tabla3[[#This Row],[PATENTE]],'ENERO 2025'!$A:$D,4,0) -> 42.126666 | M12: =VLOOKUP(Tabla3[[#This Row],[PATENTE]],'FEBRERO 2025'!$A:$D,4,0) -> 41.846687 | N12: =VLOOKUP(Tabla3[[#This Row],[PATENTE]],'MARZO 2025'!$A:$D,4,0) -> 41.670294 | O12: =VLOOKUP(Tabla3[[#This Row],[PATENTE]],'ABRIL 2025'!$A:$D,4,0) -> 42.365833 | P12: =VLOOKUP(Tabla3[[#This Row],[PATENTE]],'MAYO 2025'!$A:$D,4,0) -> 42.020366 | Q12: =VLOOKUP(Tabla3[[#This Row],[PATENTE]],'JUNIO 2025'!$A:$D,4,0) -> 38.793907 | R12: =VLOOKUP(Tabla3[[#This Row],[PATENTE]],'JULIO 2025'!$A:$D,4,0) -> 39.162307 | S12: =VLOOKUP(Tabla3[[#This Row],[PATENTE]],'AGOSTO 2025'!$A:$D,4,0) -> 38.180201 | T12: =VLOOKUP(Tabla3[[#This Row],[PATENTE]],'SEPTIEMBRE 2025'!$A:$D,4,0) -> 39.119936 | U12: =VLOOKUP(Tabla3[[#This Row],[PATENTE]],'OCTUBRE 2025'!$A:$D,4,0) -> 38.330332 | V12: =AVERAGE(D12:U12) -> 41.346951
B13: AC488KH | C13: IVECO 360 | D13: =VLOOKUP(Tabla3[[#This Row],[PATENTE]],'MAYO 2024'!$A:$D,4,0) -> 36.012595 | E13: =VLOOKUP(Tabla3[[#This Row],[PATENTE]],'JUNIO 2024'!$A:$D,4,0) -> 36.467418 | F13: =VLOOKUP(Tabla3[[#This Row],[PATENTE]],'JULIO 2024'!$A:$D,4,0) -> 34.417992 | G13: =VLOOKUP(Tabla3[[#This Row],[PATENTE]],'AGOSTO 2024'!$A:$D,4,0) -> 36.988691 | H13: =VLOOKUP(Tabla3[[#This Row],[PATENTE]],'SEPTIEMBRE 2024'!$A:$D,4,0) -> 38.265726 | I13: =VLOOKUP(Tabla3[[#This Row],[PATENTE]],'OCTUBRE 2024'!$A:$D,4,0) -> 34.720963 | J13: =VLOOKUP(Tabla3[[#This Row],[PATENTE]],'NOVIEMBRE 2024'!$A:$D,4,0) -> 36.129145 | K13: =VLOOKUP(Tabla3[[#This Row],[PATENTE]],'DICIEMBRE 2024'!$A:$D,4,0) -> 35.436062 | L13: =VLOOKUP(Tabla3[[#This Row],[PATENTE]],'ENERO 2025'!$A:$D,4,0) -> 33.226025 | M13: =VLOOKUP(Tabla3[[#This Row],[PATENTE]],'FEBRERO 2025'!$A:$D,4,0) -> 33.231993 | N13: =VLOOKUP(Tabla3[[#This Row],[PATENTE]],'MARZO 2025'!$A:$D,4,0) -> 36.075297 | O13: =VLOOKUP(Tabla3[[#This Row],[PATENTE]],'ABRIL 2025'!$A:$D,4,0) -> 34.371229 | P13: =VLOOKUP(Tabla3[[#This Row],[PATENTE]],'MAYO 2025'!$A:$D,4,0) -> 34.946032 | Q13: =VLOOKUP(Tabla3[[#This Row],[PATENTE]],'JUNIO 2025'!$A:$D,4,0) -> 35.337969 | R13: =VLOOKUP(Tabla3[[#This Row],[PATENTE]],'JULIO 2025'!$A:$D,4,0) -> 33.890194 | S13: =VLOOKUP(Tabla3[[#This Row],[PATENTE]],'AGOSTO 2025'!$A:$D,4,0) -> 33.493251 | T13: =VLOOKUP(Tabla3[[#This Row],[PATENTE]],'SEPTIEMBRE 2025'!$A:$D,4,0) -> 35.279224 | U13: =VLOOKUP(Tabla3[[#This Row],[PATENTE]],'OCTUBRE 2025'!$A:$D,4,0) -> 32.979443 | V13: =AVERAGE(D13:U13) -> 35.070514
B14: LLN463 | C14: IVECO 330 | D14: =VLOOKUP(Tabla3[[#This Row],[PATENTE]],'MAYO 2024'!$A:$D,4,0) -> 39.403409 | E14: =VLOOKUP(Tabla3[[#This Row],[PATENTE]],'JUNIO 2024'!$A:$D,4,0) -> 38.045521 | F14: =VLOOKUP(Tabla3[[#This Row],[PATENTE]],'JULIO 2024'!$A:$D,4,0) -> 38.859361 | G14: =VLOOKUP(Tabla3[[#This Row],[PATENTE]],'AGOSTO 2024'!$A:$D,4,0) -> 40.113808 | H14: =VLOOKUP(Tabla3[[#This Row],[PATENTE]],'SEPTIEMBRE 2024'!$A:$D,4,0) -> 39.782931 | I14: =VLOOKUP(Tabla3[[#This Row],[PATENTE]],'OCTUBRE 2024'!$A:$D,4,0) -> 40.680597 | J14: =VLOOKUP(Tabla3[[#This Row],[PATENTE]],'NOVIEMBRE 2024'!$A:$D,4,0) -> 42.916058 | K14: =VLOOKUP(Tabla3[[#This Row],[PATENTE]],'DICIEMBRE 2024'!$A:$D,4,0) -> 41.015108 | L14: =VLOOKUP(Tabla3[[#This Row],[PATENTE]],'ENERO 2025'!$A:$D,4,0) -> 38.612581 | M14: =VLOOKUP(Tabla3[[#This Row],[PATENTE]],'FEBRERO 2025'!$A:$D,4,0) -> 41.408829 | N14: =VLOOKUP(Tabla3[[#This Row],[PATENTE]],'MARZO 2025'!$A:$D,4,0) -> 36.30482 | O14: =VLOOKUP(Tabla3[[#This Row],[PATENTE]],'ABRIL 2025'!$A:$D,4,0) -> 38.354262 | P14: =VLOOKUP(Tabla3[[#This Row],[PATENTE]],'MAYO 2025'!$A:$D,4,0) -> 36.823544 | Q14: =VLOOKUP(Tabla3[[#This Row],[PATENTE]],'JUNIO 2025'!$A:$D,4,0) -> 36.570062 | R14: =VLOOKUP(Tabla3[[#This Row],[PATENTE]],'JULIO 2025'!$A:$D,4,0) -> 37.681127 | S14: =VLOOKUP(Tabla3[[#This Row],[PATENTE]],'AGOSTO 2025'!$A:$D,4,0) -> 37.228609 | T14: =VLOOKUP(Tabla3[[#This Row],[PATENTE]],'SEPTIEMBRE 2025'!$A:$D,4,0) -> 38.780224 | U14: =VLOOKUP(Tabla3[[#This Row],[PATENTE]],'OCTUBRE 2025'!$A:$D,4,0) -> 38.379281 | V14: =AVERAGE(D14:U14) -> 38.942229
C16: Promedios | D16: =AVERAGE(D3:D14) -> 38.974683 | E16: =AVERAGE(E3:E14) -> 39.179286 | F16: =AVERAGE(F3:F14) -> 39.335538 | G16: =AVERAGE(G3:G14) -> 39.970011 | H16: =AVERAGE(H3:H14) -> 40.179423 | I16: =AVERAGE(I3:I14) -> 39.994703 | J16: =AVERAGE(J3:J14) -> 39.985822 | K16: =AVERAGE(K3:K14) -> 39.727363 | ... U16: =AVERAGE(U3:U14) -> 37.558297
A18: 36 / 37 | B18: NZB189 | C18: MB 1634 | D18: =VLOOKUP(Tabla3[[#This Row],[PATENTE]],'MAYO 2024'!$A:$D,4,0) -> 38.857075 | E18: =VLOOKUP(Tabla3[[#This Row],[PATENTE]],'JUNIO 2024'!$A:$D,4,0) -> 40.29189 | G18: =VLOOKUP(Tabla3[[#This Row],[PATENTE]],'AGOSTO 2024'!$A:$D,4,0) -> 40.934767 | H18: =VLOOKUP(Tabla3[[#This Row],[PATENTE]],'SEPTIEMBRE 2024'!$A:$D,4,0) -> 40.637168 | I18: =VLOOKUP(Tabla3[[#This Row],[PATENTE]],'OCTUBRE 2024'!$A:$D,4,0) -> 38.737639 | J18: =VLOOKUP(Tabla3[[#This Row],[PATENTE]],'NOVIEMBRE 2024'!$A:$D,4,0) -> 40.96 | K18: =VLOOKUP(Tabla3[[#This Row],[PATENTE]],'DICIEMBRE 2024'!$A:$D,4,0) -> 39.514636 | L18: =VLOOKUP(Tabla3[[#This Row],[PATENTE]],'ENERO 2025'!$A:$D,4,0) -> 40.422464 | P18: =VLOOKUP(Tabla3[[#This Row],[PATENTE]],'MAYO 2025'!$A:$D,4,0) -> 38.427225 | Q18: =VLOOKUP(Tabla3[[#This Row],[PATENTE]],'JUNIO 2025'!$A:$D,4,0) -> 40.273793 | R18: =VLOOKUP(Tabla3[[#This Row],[PATENTE]],'JULIO 2025'!$A:$D,4,0) -> 39.624262 | S18: =VLOOKUP(Tabla3[[#This Row],[PATENTE]],'AGOSTO 2025'!$A:$D,4,0) -> 37.636823 | T18: =VLOOKUP(Tabla3[[#This Row],[PATENTE]],'SEPTIEMBRE 2025'!$A:$D,4,0) -> 37.747116 | U18: =VLOOKUP(Tabla3[[#This Row],[PATENTE]],'OCTUBRE 2025'!$A:$D,4,0) -> 36.547847 | V18: =AVERAGE(D18:U18) -> 39.329479
B19: OYD523 | C19: MB 1634 | E19: =VLOOKUP(Tabla3[[#This Row],[PATENTE]],'JUNIO 2024'!$A:$D,4,0) -> 37.040216 | F19: =VLOOKUP(Tabla3[[#This Row],[PATENTE]],'JULIO 2024'!$A:$D,4,0) -> 39.78667 | G19: =VLOOKUP(Tabla3[[#This Row],[PATENTE]],'AGOSTO 2024'!$A:$D,4,0) -> 41.641831 | H19: =VLOOKUP(Tabla3[[#This Row],[PATENTE]],'SEPTIEMBRE 2024'!$A:$D,4,0) -> 39.078767 | I19: =VLOOKUP(Tabla3[[#This Row],[PATENTE]],'OCTUBRE 2024'!$A:$D,4,0) -> 41.930618 | J19: =VLOOKUP(Tabla3[[#This Row],[PATENTE]],'NOVIEMBRE 2024'!$A:$D,4,0) -> 42.814572 | K19: =VLOOKUP(Tabla3[[#This Row],[PATENTE]],'DICIEMBRE 2024'!$A:$D,4,0) -> 41.173378 | L19: =VLOOKUP(Tabla3[[#This Row],[PATENTE]],'ENERO 2025'!$A:$D,4,0) -> 39.791118 | M19: =VLOOKUP(Tabla3[[#This Row],[PATENTE]],'FEBRERO 2025'!$A:$D,4,0) -> 40.658219 | N19: =VLOOKUP(Tabla3[[#This Row],[PATENTE]],'MARZO 2025'!$A:$D,4,0) -> 37.182864 | O19: =VLOOKUP(Tabla3[[#This Row],[PATENTE]],'ABRIL 2025'!$A:$D,4,0) -> 37.474608 | P19: =VLOOKUP(Tabla3[[#This Row],[PATENTE]],'MAYO 2025'!$A:$D,4,0) -> 34.512808 | Q19: =VLOOKUP(Tabla3[[#This Row],[PATENTE]],'JUNIO 2025'!$A:$D,4,0) -> 35.816666 | R19: =VLOOKUP(Tabla3[[#This Row],[PATENTE]],'JULIO 2025'!$A:$D,4,0) -> 39.282182 | S19: =VLOOKUP(Tabla3[[#This Row],[PATENTE]],'AGOSTO 2025'!$A:$D,4,0) -> 37.021569 | T19: =VLOOKUP(Tabla3[[#This Row],[PATENTE]],'SEPTIEMBRE 2025'!$A:$D,4,0) -> 35.961387 | V19: =AVERAGE(D19:U19) -> 38.822967
B20: OYE456 | C20: MB 1634 | D20: =VLOOKUP(Tabla3[[#This Row],[PATENTE]],'MAYO 2024'!$A:$D,4,0) -> 40.115361 | E20: =VLOOKUP(Tabla3[[#This Row],[PATENTE]],'JUNIO 2024'!$A:$D,4,0) -> 40.253959 | F20: =VLOOKUP(Tabla3[[#This Row],[PATENTE]],'JULIO 2024'!$A:$D,4,0) -> 38.25303 | G20: =VLOOKUP(Tabla3[[#This Row],[PATENTE]],'AGOSTO 2024'!$A:$D,4,0) -> 42.600195 | H20: =VLOOKUP(Tabla3[[#This Row],[PATENTE]],'SEPTIEMBRE 2024'!$A:$D,4,0) -> 42.907622 | I20: =VLOOKUP(Tabla3[[#This Row],[PATENTE]],'OCTUBRE 2024'!$A:$D,4,0) -> 42.277563 | J20: =VLOOKUP(Tabla3[[#This Row],[PATENTE]],'NOVIEMBRE 2024'!$A:$D,4,0) -> 43.169819 | K20: =VLOOKUP(Tabla3[[#This Row],[PATENTE]],'DICIEMBRE 2024'!$A:$D,4,0) -> 41.903739 | L20: =VLOOKUP(Tabla3[[#This Row],[PATENTE]],'ENERO 2025'!$A:$D,4,0) -> 40.174093 | M20: =VLOOKUP(Tabla3[[#This Row],[PATENTE]],'FEBRERO 2025'!$A:$D,4,0) -> 37.259291 | N20: =VLOOKUP(Tabla3[[#This Row],[PATENTE]],'MARZO 2025'!$A:$D,4,0) -> 35.846049 | O20: =VLOOKUP(Tabla3[[#This Row],[PATENTE]],'ABRIL 2025'!$A:$D,4,0) -> 38.613035 | P20: =VLOOKUP(Tabla3[[#This Row],[PATENTE]],'MAYO 2025'!$A:$D,4,0) -> 36.966498 | Q20: =VLOOKUP(Tabla3[[#This Row],[PATENTE]],'JUNIO 2025'!$A:$D,4,0) -> 38.092028 | R20: =VLOOKUP(Tabla3[[#This Row],[PATENTE]],'JULIO 2025'!$A:$D,4,0) -> 39.643243 | S20: =VLOOKUP(Tabla3[[#This Row],[PATENTE]],'AGOSTO 2025'!$A:$D,4,0) -> 39.414952 | T20: =VLOOKUP(Tabla3[[#This Row],[PATENTE]],'SEPTIEMBRE 2025'!$A:$D,4,0) -> 39.574403 | U20: =VLOOKUP(Tabla3[[#This Row],[PATENTE]],'OCTUBRE 2025'!$A:$D,4,0) -> 38.381317 | V20: =AVERAGE(D20:U20) -> 39.747011
B21: PNH470 | C21: MB 1634 | D21: =VLOOKUP(Tabla3[[#This Row],[PATENTE]],'MAYO 2024'!$A:$D,4,0) -> 38.504815 | E21: =VLOOKUP(Tabla3[[#This Row],[PATENTE]],'JUNIO 2024'!$A:$D,4,0) -> 36.311198 | F21: =VLOOKUP(Tabla3[[#This Row],[PATENTE]],'JULIO 2024'!$A:$D,4,0) -> 36.221522 | G21: =VLOOKUP(Tabla3[[#This Row],[PATENTE]],'AGOSTO 2024'!$A:$D,4,0) -> 38.952644 | H21: =VLOOKUP(Tabla3[[#This Row],[PATENTE]],'SEPTIEMBRE 2024'!$A:$D,4,0) -> 38.936422 | I21: =VLOOKUP(Tabla3[[#This Row],[PATENTE]],'OCTUBRE 2024'!$A:$D,4,0) -> 37.155797 | J21: =VLOOKUP(Tabla3[[#This Row],[PATENTE]],'NOVIEMBRE 2024'!$A:$D,4,0) -> 38.314706 | K21: =VLOOKUP(Tabla3[[#This Row],[PATENTE]],'DICIEMBRE 2024'!$A:$D,4,0) -> 36.366138 | L21: =VLOOKUP(Tabla3[[#This Row],[PATENTE]],'ENERO 2025'!$A:$D,4,0) -> 37.71957 | M21: =VLOOKUP(Tabla3[[#This Row],[PATENTE]],'FEBRERO 2025'!$A:$D,4,0) -> 37.224945 | N21: =VLOOKUP(Tabla3[[#This Row],[PATENTE]],'MARZO 2025'!$A:$D,4,0) -> 38.251661 | O21: =VLOOKUP(Tabla3[[#This Row],[PATENTE]],'ABRIL 2025'!$A:$D,4,0) -> 37.954142 | P21: =VLOOKUP(Tabla3[[#This Row],[PATENTE]],'MAYO 2025'!$A:$D,4,0) -> 37.581518 | Q21: =VLOOKUP(Tabla3[[#This Row],[PATENTE]],'JUNIO 2025'!$A:$D,4,0) -> 37.694756 | R21: =VLOOKUP(Tabla3[[#This Row],[PATENTE]],'JULIO 2025'!$A:$D,4,0) -> 34.97355 | S21: =VLOOKUP(Tabla3[[#This Row],[PATENTE]],'AGOSTO 2025'!$A:$D,4,0) -> 36.430354 | T21: =VLOOKUP(Tabla3[[#This Row],[PATENTE]],'SEPTIEMBRE 2025'!$A:$D,4,0) -> 37.357071 | U21: =VLOOKUP(Tabla3[[#This Row],[PATENTE]],'OCTUBRE 2025'!$A:$D,4,0) -> 39.311452 | V21: =AVERAGE(D21:U21) -> 37.51457
B22: PCK145 | C22: MB 1634 | D22: =VLOOKUP(Tabla3[[#This Row],[PATENTE]],'MAYO 2024'!$A:$D,4,0) -> 39.360983 | E22: =VLOOKUP(Tabla3[[#This Row],[PATENTE]],'JUNIO 2024'!$A:$D,4,0) -> 39.049645 | F22: =VLOOKUP(Tabla3[[#This Row],[PATENTE]],'JULIO 2024'!$A:$D,4,0) -> 39.711117 | G22: =VLOOKUP(Tabla3[[#This Row],[PATENTE]],'AGOSTO 2024'!$A:$D,4,0) -> 39.447008 | H22: =VLOOKUP(Tabla3[[#This Row],[PATENTE]],'SEPTIEMBRE 2024'!$A:$D,4,0) -> 40.292111 | I22: =VLOOKUP(Tabla3[[#This Row],[PATENTE]],'OCTUBRE 2024'!$A:$D,4,0) -> 39.363455 | J22: =VLOOKUP(Tabla3[[#This Row],[PATENTE]],'NOVIEMBRE 2024'!$A:$D,4,0) -> 39.774622 | K22: =VLOOKUP(Tabla3[[#This Row],[PATENTE]],'DICIEMBRE 2024'!$A:$D,4,0) -> 40.615872 | L22: =VLOOKUP(Tabla3[[#This Row],[PATENTE]],'ENERO 2025'!$A:$D,4,0) -> 38.146603 | M22: =VLOOKUP(Tabla3[[#This Row],[PATENTE]],'FEBRERO 2025'!$A:$D,4,0) -> 37.397366 | N22: =VLOOKUP(Tabla3[[#This Row],[PATENTE]],'MARZO 2025'!$A:$D,4,0) -> 38.765412 | O22: =VLOOKUP(Tabla3[[#This Row],[PATENTE]],'ABRIL 2025'!$A:$D,4,0) -> 35.798001 | P22: =VLOOKUP(Tabla3[[#This Row],[PATENTE]],'MAYO 2025'!$A:$D,4,0) -> 36.139777 | Q22: =VLOOKUP(Tabla3[[#This Row],[PATENTE]],'JUNIO 2025'!$A:$D,4,0) -> 39.099972 | R22: =VLOOKUP(Tabla3[[#This Row],[PATENTE]],'JULIO 2025'!$A:$D,4,0) -> 38.979868 | S22: =VLOOKUP(Tabla3[[#This Row],[PATENTE]],'AGOSTO 2025'!$A:$D,4,0) -> 38.264719 | T22: =VLOOKUP(Tabla3[[#This Row],[PATENTE]],'SEPTIEMBRE 2025'!$A:$D,4,0) -> 38.985543 | U22: =VLOOKUP(Tabla3[[#This Row],[PATENTE]],'OCTUBRE 2025'!$A:$D,4,0) -> 40.532414 | V22: =AVERAGE(D22:U22) -> 38.873583
